Workbook

Sheet Cover
B6: FoxEco
B8: TEST CASE & TEST REPORT
B9: Bộ tài liệu kiểm thử — quy trình SDLC
C12: Mã hiệu | E12: 7.1-BM/PM/HDCV/ISC
C13: Phiên bản | E13: 1.1
B15: File gồm 2 phần: TEST CASE (viết & theo dõi case) và REPORT (tổng hợp kết quả & bug).
B16: Sheet: Guideline · Revision History · Summary · Dashboard · Report Test · Data · RTM· Test Cases

Sheet Guideline
B2: QUY ĐỊNH CHUNG
B3: 1. Đặt tên file | C3: ISC_[Tên dự án]_[Version]_TC_[Version TC]_R[Số round test].xlsx VD: ISC_FCP-Web_v1.0_TC_v1.0_R1.xls
B4: 2. Tách sheet | C4: Mỗi Function/Screen tách thành 1 sheet Test Cases riêng (copy sheet mẫu).
B5: 3. Test Title | C5: Mỗi case kiểm tra 1 nội dung; bắt đầu bằng 'Check ...'
B6: 4. Người thực hiện | C6: Dùng email, mỗi case 1 người
B7: 5. Phiên bản | C7: Khi update nội dung file test cases phải tăng [Version TC] và quản lý lịch sử thay đổi trong sheet Revision History
B10: PHÂN LOẠI TRẠNG THÁI (Status — trạng thái TỔNG của TC)
B11: Trạng thái | C11: Ý nghĩa
B12: Pass | C12: Đạt — chỉ Pass khi TẤT CẢ bước/kiểm tra trong case đều đạt
B13: Fail | C13: Chỉ cần 1 bước/kiểm tra không đạt → Fail (ghi ID Bugs)
B14: Block | C14: Không thực hiện được / Pending — ghi rõ lý do ở Remark
B15: N/A | C15: Case không áp dụng (VD: Won't fix)
B18: PHÂN LOẠI ĐỘ ƯU TIÊN
B19: Priority | C19: Ý nghĩa
B20: High (P1) | C20: Bắt buộc chạy; ảnh hưởng luồng/nghiệp vụ chính
B21: Medium (P2) | C21: Chạy ít nhất 1 lần; ảnh hưởng người dùng mức trung bình
B22: Low (P3) | C22: Có thể bỏ khi rút ngắn thời gian; ít ảnh hưởng
B25: PHÂN LOẠI NHÓM (Group)
B26: Group | C26: Ý nghĩa
B27: Functional | C27: Kiểm tra chức năng theo luồng nghiệp vụ
B28: UI | C28: Kiểm tra giao diện: bố cục, hiển thị, responsive, thông báo, trạng thái control
B29: Integration | C29: Kiểm tra tích hợp giữa các module / API / hệ thống
B30: Database | C30: Kiểm tra tầng dữ liệu: lưu/đọc đúng, ràng buộc & toàn vẹn dữ liệu (CSDL)
B33: Ý NGHĨA CỘT EXECUTION
B34: Status | C34: Trạng thái TỔNG của TC = kết quả round MỚI NHẤT (tự động, không nhập tay).
B35: Executed By (mỗi round) | C35: Email người thực thi test ở TỪNG round.
B36: ID Bugs (mỗi round) | C36: Mã bug (Jira) phát sinh ở round đó khi Fail.
B39: SDLC
B40: Các cột dưới đây tích hợp AI vào quy trình kiểm thử
B41: Origin (Nguồn tạo) | C41: AI = TC do AI sinh · QC = QC viết tay
B42: Review | C42: Reviewed = QC đã review · Pending = chờ review · N/A
B43: Automated | C43: Yes/No — TC đã được viết script automation hay chưa
B44: Script | C44: Đường dẫn file script automation (nếu có)
B45: Vibe-test | C45: Yes/No/N-A theo TỪNG round — TC có kiểm thử kiểu 'vibe-test' (thăm dò có AI agent hỗ trợ) ở round đó. Cột 'Vibe-test (tổng)' tự gộp = Yes nếu có ≥1 round Yes.
B46: KQ Script | C46: Kết quả CHẠY script tự động theo TỪNG round: Pass/Fail/Block/N/A/Chưa chạy. Cột 'KQ Script (tổng)' tự lấy kết quả round mới nhất.
B47: Traceability | C47: Scenario ID + Req ID + DOC Source: truy vết TC ↔ kịch bản ↔ yêu cầu ↔ tài liệu nguồn
B49: TEST THEO ROUND (nhiều round trong 1 version)
B50: R1 … R5 | C50: Mỗi round là 1 khối 5 cột: Vibe-test · KQ Script · Kết quả · Executed By · ID Bugs. Chạy round nào thì nhập vào khối round đó. Template hỗ trợ 5 round.
B51: Status | C51: TỰ ĐỘNG = kết quả (Kết quả) của round MỚI NHẤT trong R1…R5. Không nhập tay.
B52: Round (Bug Data) | C52: Round phát hiện bug. Report mục IV thống kê Bug theo round & tiến độ Pass/Fail theo round.

Sheet Revision History
D3: REVISION HISTORY
B6: Date | C6: Version | D6: Author | E6: Reviewer | F6: Approver | G6: Change Description
B7: 46231 | C7: 1 | D7: GiangDC2 | E7: — | F7: — | G7: Tạo mới — consolidate 3 fragment (Hoạt động/Cá nhân/Thông báo) v1.0, comprehensive mode
B8: 46231.781 | C8: 2 | D8: GiangDC2 | E8: — | F8: — | G8: Consolidate thêm Đăng tin (Test Case 4, TC_04, 100 TC) vào TC-MASTER — 162 TC tổng cộng (Hoạt động 20 + Cá nhân 15 + Thông báo 27 + Đăng tin 100). Dashboard +1 row, RTM +11 Req ID row, Coverage Matrix - Đăng tin thêm mới.
B9: 46232 | C9: 3 | D9: GiangDC2 | E9: — | F9: — | G9: SYNC: (1) Đưa +13 TC mới của Đăng tin (Block Người gửi/Người nhận, autocomplete địa chỉ, SC-ORD-031/032, đã có sẵn trong fragment/TC-MASTER 2026-07-29 nhưng chưa vào file ISC chính) vào ISC_FoxEco_v1.0_TC_v1_R1.xlsx — Đăng tin 100→113 TC, tổng 162→175 TC. (2) Patch 3 ô Expected Result còn sót hedge text cũ "⚠ QA đề xuất, chưa BA confirm chính thức" (Hoạt động dòng 27-28, Thông báo dòng 29) sang text đã Resolved khớp với fragment (C-ORD-06).
B10: 46233 | C10: 4 | D10: GiangDC2 | E10: — | F10: — | G10: CONSOLIDATE toàn bộ 9 fragment v1.0 → TC-MASTER: thêm 5 sheet chức năng mới Test Case 5 (TC_05 Trang chủ 32 TC), Test Case 6 (TC_06 Bảng tin & Chi tiết tin 31), Test Case 7 (TC_07 Theo dõi đơn 44), Test Case 8 (TC_08 Huỷ đơn 27), Test Case 9 (TC_09 Tặng quà 16); đồng bộ lại 4 sheet cũ theo fragment mới nhất (Hoạt động 20 / Cá nhân 15 / Thông báo 27 / Đăng tin 109). Tổng 321 TC / 9 sheet. Dashboard +5 dòng (công thức Tổng TC đếm cột C cho cả 30 dòng). RTM: 23 → 41 Req ID (+18), toàn bộ công thức E/F/G/H nối đủ 9 term COUNTIF theo 9 sheet, dòng Tổng dời xuống row 47 với range SUM E6:E46, ghi chú cuối bảng cập nhật "9 sheet", conditional formatting gap mở rộng B6:J46. 9 sheet Coverage Matrix refresh từ fragment (comprehensive mode).
B11: 46233 | C11: 5 | D11: GiangDC2 | E11: — | F11: — | G11: FIX toàn bộ 12 finding của /review-tc 2026-07-30 (2 MAJOR + 10 MINOR). +2 TC màn "Quà đã nhận" (TC_02.16 completeness 3 thành phần, TC_02.17 danh sách lịch sử — đóng gap R2-15) → 321→323 TC. Viết lại Remark TC_03.1/2/3 theo trần 5 thông báo/tin đã chốt. Viết lại TC_03.8/TC_03.10 chỉ assert vế thông báo + dedupe sang TC_07. Coverage Matrix: SC-NTF-006 (DEPRECATED) → SC-ASN-013; tách SC-ORD-004/005; footer Trang chủ 31→32; Cá nhân 15→17. Chuẩn hoá 27 DOC Source phi-tài-liệu. Sửa Remark VAL-02→N/A baseline (TC_04.81/82), Expected TC_04.93 + TC_04.106.

Sheet Summary
B2: SUMMARY — Thiết lập chung & Chỉ số Test Case
B3: Sheet SETUP CHUNG. Chỉ số TỔNG QUAN bên dưới được GOM TỰ ĐỘNG từ TẤT CẢ sheet Test Case, quản lý ở sheet "Dashboard".
B5: THIẾT LẬP CHUNG
B6: Tên dự án | C6: FoxEco
B7: Mã tài liệu | C7: 7.1-BM/PM/HDCV/ISC
B8: Version | C8: v1.0
B9: Sprint | C9: N/A (Solo — không chia sprint)
B10: Ngày bắt đầu test | C10: 46231
B11: Ngày kết thúc test | C11: 46231
B12: Số sheet chức năng | C12: =COUNTIF(Dashboard!$D$4:$D$33,"?*")
B13: PIC | C13: GiangDC2
B14: Ô vàng = nhập tay. Version / ngày test được Test Cases & Report tham chiếu tự động.
B16: TỔNG QUAN TEST CASE — ƯU TIÊN & TIẾN ĐỘ THỰC THI
B17: Tổng số Test Case | C17: =Dashboard!$F$34 | I17: THEO NHÓM LOẠI TC (Group)
B18: Mức ưu tiên | C18: Tổng TC | D18: % / Tổng | E18: Đã chạy | F18: % đã chạy | I18: Nhóm | J18: Số TC
B19: High (P1) | C19: =Dashboard!$O$34 | D19: =IFERROR(C19/$C$17,0) | E19: =Dashboard!$AB$34 | F19: =IFERROR(E19/C19,0) | I19: Functional | J19: =Dashboard!$R$34
B20: Medium (P2) | C20: =Dashboard!$P$34 | D20: =IFERROR(C20/$C$17,0) | E20: =Dashboard!$AC$34 | F20: =IFERROR(E20/C20,0) | I20: UI | J20: =Dashboard!$S$34
B21: Low (P3) | C21: =Dashboard!$Q$34 | D21: =IFERROR(C21/$C$17,0) | E21: =Dashboard!$AD$34 | F21: =IFERROR(E21/C21,0) | I21: Integration | J21: =Dashboard!$T$34
B22: Tổng | C22: =SUM(C19:C21) | D22: =IFERROR(C22/$C$17,0) | E22: =SUM(E19:E21) | F22: =IFERROR(E22/C22,0) | I22: Database | J22: =Dashboard!$U$34
B42: SDLC — MỨC ĐỘ ÁP DỤNG
B43: Chỉ số | C43: Số lượng | D43: % / Tổng TC
B44: TC do AI sinh (Origin=AI) | C44: =Dashboard!$V$34 | D44: =IFERROR(C44/$C17,0)
B45: TC do QC viết (Origin=QC) | C45: =Dashboard!$W$34 | D45: =IFERROR(C45/$C17,0)
B46: TC đã automation (Automated=Yes) | C46: =Dashboard!$X$34 | D46: =IFERROR(C46/$C17,0)
B47: TC Vibe-test (Yes) | C47: =Dashboard!$Y$34 | D47: =IFERROR(C47/$C17,0)
B48: TC script auto chạy Pass | C48: =Dashboard!$Z$34 | D48: =IFERROR(C48/$C17,0)
B49: TC đã TL review | C49: =Dashboard!$AA$34 | D49: =IFERROR(C49/$C17,0)
B51: % tính trên TỔNG SỐ TEST CASE. Tự đếm từ sheet Test Cases (khác khối III của Report — khối đó nhập tay theo bug).
B53: Test nhiều Round/1 version: nhập kết quả từng round ở cột R1…R8 (sheet Test Case); Status = round mới nhất. Chi tiết tiến độ theo round ở Report — mục IV.
B56: MÔI TRƯỜNG & PHẠM VI TEST
B57: Environment | C57: Staging
B58: Platform | C58: Web / Android / iOS
B59: Device | C59: VD: iPhone 14 (iOS 17), Galaxy S23 (Android 14)
B60: Accounts | C60: VD: user01, user02
B61: Functional Testing | C61: VD: 1. Function A / 2. Function B
B62: System Integration Testing (nếu có) | C62: VD: Tool A, Tool B
B64: ► QUẢN LÝ DANH SÁCH SHEET TEST CASE: xem sheet "Dashboard". Thêm/bớt function chỉ cần thêm/xoá 1 dòng (tên tab sheet) ở Dashboard — mọi chỉ số tự cập nhật.

Sheet Dashboard
B1: BẢNG ĐIỀU KHIỂN — QUẢN LÝ & GOM SỐ LIỆU TẤT CẢ SHEET TEST CASE
C2: QUẢN LÝ SHEET (nhập tay 3 cột) | F2: Execution | O2: PRIORITY | R2: GROUP TC | V2: SDLC | AB2: PRIORITY — ĐÃ CHẠY | AE2: TIẾN ĐỘ THEO ROUND (mỗi round chạy lại toàn bộ TC)
B3: STT | C3: Mã CN | D3: Tên tab sheet (đúng 100%) | E3: Function / Màn hình | F3: Tổng TC | G3: Pass | H3: Fail | I3: Block | J3: N/A | K3: Chưa chạy | L3: Executed | M3: Coverage % | N3: Pass % | O3: High | P3: Medium | Q3: Low | R3: Functional | S3: UI | T3: Integration | U3: Database | V3: AI-gen | W3: QC viết | X3: Auto | Y3: Vibe | Z3: Script Pass | AA3: Reviewed | AB3: High đã chạy | AC3: Medium đã chạy | AD3: Low đã chạy | AE3: R1 Executed | AF3: R1 Pass | AG3: R1 Fail | AH3: R1 Block | AI3: R1 N/A | AJ3: R2 Executed | AK3: R2 Pass | AL3: R2 Fail | AM3: R2 Block | AN3: R2 N/A | AO3: R3 Executed | AP3: R3 Pass | AQ3: R3 Fail | AR3: R3 Block | AS3: R3 N/A | AT3: R4 Executed | AU3: R4 Pass | AV3: R4 Fail | AW3: R4 Block | AX3: R4 N/A | AY3: R5 Executed | AZ3: R5 Pass | BA3: R5 Fail | BB3: R5 Block | BC3: R5 N/A
B4: =IF($D4="","",ROW()-3) | C4: TC_01 | D4: Hoạt động | E4: Hoạt động (Đơn của tôi) | F4: =IF($D4="","",IFERROR(COUNTIF(INDIRECT("'"&$D4&"'!$C$7:$C$500"),"?*"),0)) | G4: =IF($D4="","",IFERROR(COUNTIF(INDIRECT("'"&$D4&"'!$AO$7:$AO$500"),"Pass"),0)) | H4: =IF($D4="","",IFERROR(COUNTIF(INDIRECT("'"&$D4&"'!$AO$7:$AO$500"),"Fail"),0)) | I4: =IF($D4="","",IFERROR(COUNTIF(INDIRECT("'"&$D4&"'!$AO$7:$AO$500"),"Block"),0)) | J4: =IF($D4="","",IFERROR(COUNTIF(INDIRECT("'"&$D4&"'!$AO$7:$AO$500"),"N/A"),0)) | K4: =IF($D4="","",MAX(0,$F4-$G4-$H4-$I4-$J4)) | L4: =IF($D4="","",$G4+$H4+$I4+$J4) | M4: =IF($D4="","",IFERROR($L4/$F4,0)) | N4: =IF($D4="","",IFERROR($G4/$L4,0)) | O4: =IF($D4="","",IFERROR(COUNTIF(INDIRECT("'"&$D4&"'!$E$7:$E$500"),"High"),0)) | P4: =IF($D4="","",IFERROR(COUNTIF(INDIRECT("'"&$D4&"'!$E$7:$E$500"),"Medium"),0)) | Q4: =IF($D4="","",IFERROR(COUNTIF(INDIRECT("'"&$D4&"'!$E$7:$E$500"),"Low"),0)) | R4: =IF($D4="","",IFERROR(COUNTIF(INDIRECT("'"&$D4&"'!$D$7:$D$500"),"Functional"),0)) | S4: =IF($D4="","",IFERROR(COUNTIF(INDIRECT("'"&$D4&"'!$D$7:$D$500"),"UI"),0)) | T4: =IF($D4="","",IFERROR(COUNTIF(INDIRECT("'"&$D4&"'!$D$7:$D$500"),"Integration"),0)) | U4: =IF($D4="","",IFERROR(COUNTIF(INDIRECT("'"&$D4&"'!$D$7:$D$500"),"Database Test Case"),0)) | V4: =IF($D4="","",IFERROR(COUNTIF(INDIRECT("'"&$D4&"'!$J$7:$J$500"),"AI"),0)) | W4: =IF($D4="","",IFERROR(COUNTIF(INDIRECT("'"&$D4&"'!$J$7:$J$500"),"QC"),0)) | X4: =IF($D4="","",IFERROR(COUNTIF(INDIRECT("'"&$D4&"'!$L$7:$L$500"),"Yes"),0)) | Y4: =IF($D4="","",IFERROR(COUNTIF(INDIRECT("'"&$D4&"'!$AM$7:$AM$500"),"Yes"),0)) | Z4: =IF($D4="","",IFERROR(COUNTIF(INDIRECT("'"&$D4&"'!$AN$7:$AN$500"),"Pass"),0)) | AA4: =IF($D4="","",IFERROR(COUNTIF(INDIRECT("'"&$D4&"'!$K$7:$K$500"),"Reviewed"),0)) | AB4: =IF($D4="","",IFERROR(SUMPRODUCT((INDIRECT("'"&$D4&"'!$E$7:$E$500")="High")*(INDIRECT("'"&$D4&"'!$AO$7:$AO$500")<>"")),0)) | AC4: =IF($D4="","",IFERROR(SUMPRODUCT((INDIRECT("'"&$D4&"'!$E$7:$E$500")="Medium")*(INDIRECT("'"&$D4&"'!$AO$7:$AO$500")<>"")),0)) | AD4: =IF($D4="","",IFERROR(SUMPRODUCT((INDIRECT("'"&$D4&"'!$E$7:$E$500")="Low")*(INDIRECT("'"&$D4&"'!$AO$7:$AO$500")<>"")),0)) | AE4: =IF($D4="","",IFERROR(COUNTIF(INDIRECT("'"&$D4&"'!$P$7:$P$500"),"<>"),0)) | AF4: =IF($D4="","",IFERROR(COUNTIF(INDIRECT("'"&$D4&"'!$P$7:$P$500"),"Pass"),0)) | AG4: =IF($D4="","",IFERROR(COUNTIF(INDIRECT("'"&$D4&"'!$P$7:$P$500"),"Fail"),0)) | AH4: =IF($D4="","",IFERROR(COUNTIF(INDIRECT("'"&$D4&"'!$P$7:$P$500"),"Block"),0)) | AI4: =IF($D4="","",IFERROR(COUNTIF(INDIRECT("'"&$D4&"'!$P$7:$P$500"),"N/A"),0)) | AJ4: =IF($D4="","",IFERROR(COUNTIF(INDIRECT("'"&$D4&"'!$U$7:$U$500"),"<>"),0)) | AK4: =IF($D4="","",IFERROR(COUNTIF(INDIRECT("'"&$D4&"'!$U$7:$U$500"),"Pass"),0)) | AL4: =IF($D4="","",IFERROR(COUNTIF(INDIRECT("'"&$D4&"'!$U$7:$U$500"),"Fail"),0)) | AM4: =IF($D4="","",IFERROR(COUNTIF(INDIRECT("'"&$D4&"'!$U$7:$U$500"),"Block"),0)) | AN4: =IF($D4="","",IFERROR(COUNTIF(INDIRECT("'"&$D4&"'!$U$7:$U$500"),"N/A"),0)) | AO4: =IF($D4="","",IFERROR(COUNTIF(INDIRECT("'"&$D4&"'!$Z$7:$Z$500"),"<>"),0)) | AP4: =IF($D4="","",IFERROR(COUNTIF(INDIRECT("'"&$D4&"'!$Z$7:$Z$500"),"Pass"),0)) | AQ4: =IF($D4="","",IFERROR(COUNTIF(INDIRECT("'"&$D4&"'!$Z$7:$Z$500"),"Fail"),0)) | AR4: =IF($D4="","",IFERROR(COUNTIF(INDIRECT("'"&$D4&"'!$Z$7:$Z$500"),"Block"),0)) | AS4: =IF($D4="","",IFERROR(COUNTIF(INDIRECT("'"&$D4&"'!$Z$7:$Z$500"),"N/A"),0)) | AT4: =IF($D4="","",IFERROR(COUNTIF(INDIRECT("'"&$D4&"'!$AE$7:$AE$500"),"<>"),0)) | AU4: =IF($D4="","",IFERROR(COUNTIF(INDIRECT("'"&$D4&"'!$AE$7:$AE$500"),"Pass"),0)) | AV4: =IF($D4="","",IFERROR(COUNTIF(INDIRECT("'"&$D4&"'!$AE$7:$AE$500"),"Fail"),0)) | AW4: =IF($D4="","",IFERROR(COUNTIF(INDIRECT("'"&$D4&"'!$AE$7:$AE$500"),"Block"),0)) | AX4: =IF($D4="","",IFERROR(COUNTIF(INDIRECT("'"&$D4&"'!$AE$7:$AE$500"),"N/A"),0)) | AY4: =IF($D4="","",IFERROR(COUNTIF(INDIRECT("'"&$D4&"'!$AJ$7:$AJ$500"),"<>"),0)) | AZ4: =IF($D4="","",IFERROR(COUNTIF(INDIRECT("'"&$D4&"'!$AJ$7:$AJ$500"),"Pass"),0)) | BA4: =IF($D4="","",IFERROR(COUNTIF(INDIRECT("'"&$D4&"'!$AJ$7:$AJ$500"),"Fail"),0)) | BB4: =IF($D4="","",IFERROR(COUNTIF(INDIRECT("'"&$D4&"'!$AJ$7:$AJ$500"),"Block"),0)) | BC4: =IF($D4="","",IFERROR(COUNTIF(INDIRECT("'"&$D4&"'!$AJ$7:$AJ$500"),"N/A"),0))
B5: =IF($D5="","",ROW()-3) | C5: TC_02 | D5: Cá nhân | E5: Cá nhân | F5: =IF($D5="","",IFERROR(COUNTIF(INDIRECT("'"&$D5&"'!$C$7:$C$500"),"?*"),0)) | G5: =IF($D5="","",IFERROR(COUNTIF(INDIRECT("'"&$D5&"'!$AO$7:$AO$500"),"Pass"),0)) | H5: =IF($D5="","",IFERROR(COUNTIF(INDIRECT("'"&$D5&"'!$AO$7:$AO$500"),"Fail"),0)) | I5: =IF($D5="","",IFERROR(COUNTIF(INDIRECT("'"&$D5&"'!$AO$7:$AO$500"),"Block"),0)) | J5: =IF($D5="","",IFERROR(COUNTIF(INDIRECT("'"&$D5&"'!$AO$7:$AO$500"),"N/A"),0)) | K5: =IF($D5="","",MAX(0,$F5-$G5-$H5-$I5-$J5)) | L5: =IF($D5="","",$G5+$H5+$I5+$J5) | M5: =IF($D5="","",IFERROR($L5/$F5,0)) | N5: =IF($D5="","",IFERROR($G5/$L5,0)) | O5: =IF($D5="","",IFERROR(COUNTIF(INDIRECT("'"&$D5&"'!$E$7:$E$500"),"High"),0)) | P5: =IF($D5="","",IFERROR(COUNTIF(INDIRECT("'"&$D5&"'!$E$7:$E$500"),"Medium"),0)) | Q5: =IF($D5="","",IFERROR(COUNTIF(INDIRECT("'"&$D5&"'!$E$7:$E$500"),"Low"),0)) | R5: =IF($D5="","",IFERROR(COUNTIF(INDIRECT("'"&$D5&"'!$D$7:$D$500"),"Functional"),0)) | S5: =IF($D5="","",IFERROR(COUNTIF(INDIRECT("'"&$D5&"'!$D$7:$D$500"),"UI"),0)) | T5: =IF($D5="","",IFERROR(COUNTIF(INDIRECT("'"&$D5&"'!$D$7:$D$500"),"Integration"),0)) | U5: =IF($D5="","",IFERROR(COUNTIF(INDIRECT("'"&$D5&"'!$D$7:$D$500"),"Database Test Case"),0)) | V5: =IF($D5="","",IFERROR(COUNTIF(INDIRECT("'"&$D5&"'!$J$7:$J$500"),"AI"),0)) | W5: =IF($D5="","",IFERROR(COUNTIF(INDIRECT("'"&$D5&"'!$J$7:$J$500"),"QC"),0)) | X5: =IF($D5="","",IFERROR(COUNTIF(INDIRECT("'"&$D5&"'!$L$7:$L$500"),"Yes"),0)) | Y5: =IF($D5="","",IFERROR(COUNTIF(INDIRECT("'"&$D5&"'!$AM$7:$AM$500"),"Yes"),0)) | Z5: =IF($D5="","",IFERROR(COUNTIF(INDIRECT("'"&$D5&"'!$AN$7:$AN$500"),"Pass"),0)) | AA5: =IF($D5="","",IFERROR(COUNTIF(INDIRECT("'"&$D5&"'!$K$7:$K$500"),"Reviewed"),0)) | AB5: =IF($D5="","",IFERROR(SUMPRODUCT((INDIRECT("'"&$D5&"'!$E$7:$E$500")="High")*(INDIRECT("'"&$D5&"'!$AO$7:$AO$500")<>"")),0)) | AC5: =IF($D5="","",IFERROR(SUMPRODUCT((INDIRECT("'"&$D5&"'!$E$7:$E$500")="Medium")*(INDIRECT("'"&$D5&"'!$AO$7:$AO$500")<>"")),0)) | AD5: =IF($D5="","",IFERROR(SUMPRODUCT((INDIRECT("'"&$D5&"'!$E$7:$E$500")="Low")*(INDIRECT("'"&$D5&"'!$AO$7:$AO$500")<>"")),0)) | AE5: =IF($D5="","",IFERROR(COUNTIF(INDIRECT("'"&$D5&"'!$P$7:$P$500"),"<>"),0)) | AF5: =IF($D5="","",IFERROR(COUNTIF(INDIRECT("'"&$D5&"'!$P$7:$P$500"),"Pass"),0)) | AG5: =IF($D5="","",IFERROR(COUNTIF(INDIRECT("'"&$D5&"'!$P$7:$P$500"),"Fail"),0)) | AH5: =IF($D5="","",IFERROR(COUNTIF(INDIRECT("'"&$D5&"'!$P$7:$P$500"),"Block"),0)) | AI5: =IF($D5="","",IFERROR(COUNTIF(INDIRECT("'"&$D5&"'!$P$7:$P$500"),"N/A"),0)) | AJ5: =IF($D5="","",IFERROR(COUNTIF(INDIRECT("'"&$D5&"'!$U$7:$U$500"),"<>"),0)) | AK5: =IF($D5="","",IFERROR(COUNTIF(INDIRECT("'"&$D5&"'!$U$7:$U$500"),"Pass"),0)) | AL5: =IF($D5="","",IFERROR(COUNTIF(INDIRECT("'"&$D5&"'!$U$7:$U$500"),"Fail"),0)) | AM5: =IF($D5="","",IFERROR(COUNTIF(INDIRECT("'"&$D5&"'!$U$7:$U$500"),"Block"),0)) | AN5: =IF($D5="","",IFERROR(COUNTIF(INDIRECT("'"&$D5&"'!$U$7:$U$500"),"N/A"),0)) | AO5: =IF($D5="","",IFERROR(COUNTIF(INDIRECT("'"&$D5&"'!$Z$7:$Z$500"),"<>"),0)) | AP5: =IF($D5="","",IFERROR(COUNTIF(INDIRECT("'"&$D5&"'!$Z$7:$Z$500"),"Pass"),0)) | AQ5: =IF($D5="","",IFERROR(COUNTIF(INDIRECT("'"&$D5&"'!$Z$7:$Z$500"),"Fail"),0)) | AR5: =IF($D5="","",IFERROR(COUNTIF(INDIRECT("'"&$D5&"'!$Z$7:$Z$500"),"Block"),0)) | AS5: =IF($D5="","",IFERROR(COUNTIF(INDIRECT("'"&$D5&"'!$Z$7:$Z$500"),"N/A"),0)) | AT5: =IF($D5="","",IFERROR(COUNTIF(INDIRECT("'"&$D5&"'!$AE$7:$AE$500"),"<>"),0)) | AU5: =IF($D5="","",IFERROR(COUNTIF(INDIRECT("'"&$D5&"'!$AE$7:$AE$500"),"Pass"),0)) | AV5: =IF($D5="","",IFERROR(COUNTIF(INDIRECT("'"&$D5&"'!$AE$7:$AE$500"),"Fail"),0)) | AW5: =IF($D5="","",IFERROR(COUNTIF(INDIRECT("'"&$D5&"'!$AE$7:$AE$500"),"Block"),0)) | AX5: =IF($D5="","",IFERROR(COUNTIF(INDIRECT("'"&$D5&"'!$AE$7:$AE$500"),"N/A"),0)) | AY5: =IF($D5="","",IFERROR(COUNTIF(INDIRECT("'"&$D5&"'!$AJ$7:$AJ$500"),"<>"),0)) | AZ5: =IF($D5="","",IFERROR(COUNTIF(INDIRECT("'"&$D5&"'!$AJ$7:$AJ$500"),"Pass"),0)) | BA5: =IF($D5="","",IFERROR(COUNTIF(INDIRECT("'"&$D5&"'!$AJ$7:$AJ$500"),"Fail"),0)) | BB5: =IF($D5="","",IFERROR(COUNTIF(INDIRECT("'"&$D5&"'!$AJ$7:$AJ$500"),"Block"),0)) | BC5: =IF($D5="","",IFERROR(COUNTIF(INDIRECT("'"&$D5&"'!$AJ$7:$AJ$500"),"N/A"),0))
B6: =IF($D6="","",ROW()-3) | C6: TC_03 | D6: Thông báo | E6: Thông báo | F6: =IF($D6="","",IFERROR(COUNTIF(INDIRECT("'"&$D6&"'!$C$7:$C$500"),"?*"),0)) | G6: =IF($D6="","",IFERROR(COUNTIF(INDIRECT("'"&$D6&"'!$AO$7:$AO$500"),"Pass"),0)) | H6: =IF($D6="","",IFERROR(COUNTIF(INDIRECT("'"&$D6&"'!$AO$7:$AO$500"),"Fail"),0)) | I6: =IF($D6="","",IFERROR(COUNTIF(INDIRECT("'"&$D6&"'!$AO$7:$AO$500"),"Block"),0)) | J6: =IF($D6="","",IFERROR(COUNTIF(INDIRECT("'"&$D6&"'!$AO$7:$AO$500"),"N/A"),0)) | K6: =IF($D6="","",MAX(0,$F6-$G6-$H6-$I6-$J6)) | L6: =IF($D6="","",$G6+$H6+$I6+$J6) | M6: =IF($D6="","",IFERROR($L6/$F6,0)) | N6: =IF($D6="","",IFERROR($G6/$L6,0)) | O6: =IF($D6="","",IFERROR(COUNTIF(INDIRECT("'"&$D6&"'!$E$7:$E$500"),"High"),0)) | P6: =IF($D6="","",IFERROR(COUNTIF(INDIRECT("'"&$D6&"'!$E$7:$E$500"),"Medium"),0)) | Q6: =IF($D6="","",IFERROR(COUNTIF(INDIRECT("'"&$D6&"'!$E$7:$E$500"),"Low"),0)) | R6: =IF($D6="","",IFERROR(COUNTIF(INDIRECT("'"&$D6&"'!$D$7:$D$500"),"Functional"),0)) | S6: =IF($D6="","",IFERROR(COUNTIF(INDIRECT("'"&$D6&"'!$D$7:$D$500"),"UI"),0)) | T6: =IF($D6="","",IFERROR(COUNTIF(INDIRECT("'"&$D6&"'!$D$7:$D$500"),"Integration"),0)) | U6: =IF($D6="","",IFERROR(COUNTIF(INDIRECT("'"&$D6&"'!$D$7:$D$500"),"Database Test Case"),0)) | V6: =IF($D6="","",IFERROR(COUNTIF(INDIRECT("'"&$D6&"'!$J$7:$J$500"),"AI"),0)) | W6: =IF($D6="","",IFERROR(COUNTIF(INDIRECT("'"&$D6&"'!$J$7:$J$500"),"QC"),0)) | X6: =IF($D6="","",IFERROR(COUNTIF(INDIRECT("'"&$D6&"'!$L$7:$L$500"),"Yes"),0)) | Y6: =IF($D6="","",IFERROR(COUNTIF(INDIRECT("'"&$D6&"'!$AM$7:$AM$500"),"Yes"),0)) | Z6: =IF($D6="","",IFERROR(COUNTIF(INDIRECT("'"&$D6&"'!$AN$7:$AN$500"),"Pass"),0)) | AA6: =IF($D6="","",IFERROR(COUNTIF(INDIRECT("'"&$D6&"'!$K$7:$K$500"),"Reviewed"),0)) | AB6: =IF($D6="","",IFERROR(SUMPRODUCT((INDIRECT("'"&$D6&"'!$E$7:$E$500")="High")*(INDIRECT("'"&$D6&"'!$AO$7:$AO$500")<>"")),0)) | AC6: =IF($D6="","",IFERROR(SUMPRODUCT((INDIRECT("'"&$D6&"'!$E$7:$E$500")="Medium")*(INDIRECT("'"&$D6&"'!$AO$7:$AO$500")<>"")),0)) | AD6: =IF($D6="","",IFERROR(SUMPRODUCT((INDIRECT("'"&$D6&"'!$E$7:$E$500")="Low")*(INDIRECT("'"&$D6&"'!$AO$7:$AO$500")<>"")),0)) | AE6: =IF($D6="","",IFERROR(COUNTIF(INDIRECT("'"&$D6&"'!$P$7:$P$500"),"<>"),0)) | AF6: =IF($D6="","",IFERROR(COUNTIF(INDIRECT("'"&$D6&"'!$P$7:$P$500"),"Pass"),0)) | AG6: =IF($D6="","",IFERROR(COUNTIF(INDIRECT("'"&$D6&"'!$P$7:$P$500"),"Fail"),0)) | AH6: =IF($D6="","",IFERROR(COUNTIF(INDIRECT("'"&$D6&"'!$P$7:$P$500"),"Block"),0)) | AI6: =IF($D6="","",IFERROR(COUNTIF(INDIRECT("'"&$D6&"'!$P$7:$P$500"),"N/A"),0)) | AJ6: =IF($D6="","",IFERROR(COUNTIF(INDIRECT("'"&$D6&"'!$U$7:$U$500"),"<>"),0)) | AK6: =IF($D6="","",IFERROR(COUNTIF(INDIRECT("'"&$D6&"'!$U$7:$U$500"),"Pass"),0)) | AL6: =IF($D6="","",IFERROR(COUNTIF(INDIRECT("'"&$D6&"'!$U$7:$U$500"),"Fail"),0)) | AM6: =IF($D6="","",IFERROR(COUNTIF(INDIRECT("'"&$D6&"'!$U$7:$U$500"),"Block"),0)) | AN6: =IF($D6="","",IFERROR(COUNTIF(INDIRECT("'"&$D6&"'!$U$7:$U$500"),"N/A"),0)) | AO6: =IF($D6="","",IFERROR(COUNTIF(INDIRECT("'"&$D6&"'!$Z$7:$Z$500"),"<>"),0)) | AP6: =IF($D6="","",IFERROR(COUNTIF(INDIRECT("'"&$D6&"'!$Z$7:$Z$500"),"Pass"),0)) | AQ6: =IF($D6="","",IFERROR(COUNTIF(INDIRECT("'"&$D6&"'!$Z$7:$Z$500"),"Fail"),0)) | AR6: =IF($D6="","",IFERROR(COUNTIF(INDIRECT("'"&$D6&"'!$Z$7:$Z$500"),"Block"),0)) | AS6: =IF($D6="","",IFERROR(COUNTIF(INDIRECT("'"&$D6&"'!$Z$7:$Z$500"),"N/A"),0)) | AT6: =IF($D6="","",IFERROR(COUNTIF(INDIRECT("'"&$D6&"'!$AE$7:$AE$500"),"<>"),0)) | AU6: =IF($D6="","",IFERROR(COUNTIF(INDIRECT("'"&$D6&"'!$AE$7:$AE$500"),"Pass"),0)) | AV6: =IF($D6="","",IFERROR(COUNTIF(INDIRECT("'"&$D6&"'!$AE$7:$AE$500"),"Fail"),0)) | AW6: =IF($D6="","",IFERROR(COUNTIF(INDIRECT("'"&$D6&"'!$AE$7:$AE$500"),"Block"),0)) | AX6: =IF($D6="","",IFERROR(COUNTIF(INDIRECT("'"&$D6&"'!$AE$7:$AE$500"),"N/A"),0)) | AY6: =IF($D6="","",IFERROR(COUNTIF(INDIRECT("'"&$D6&"'!$AJ$7:$AJ$500"),"<>"),0)) | AZ6: =IF($D6="","",IFERROR(COUNTIF(INDIRECT("'"&$D6&"'!$AJ$7:$AJ$500"),"Pass"),0)) | BA6: =IF($D6="","",IFERROR(COUNTIF(INDIRECT("'"&$D6&"'!$AJ$7:$AJ$500"),"Fail"),0)) | BB6: =IF($D6="","",IFERROR(COUNTIF(INDIRECT("'"&$D6&"'!$AJ$7:$AJ$500"),"Block"),0)) | BC6: =IF($D6="","",IFERROR(COUNTIF(INDIRECT("'"&$D6&"'!$AJ$7:$AJ$500"),"N/A"),0))
B7: =IF($D7="","",ROW()-3) | C7: TC_04 | D7: Đăng tin | E7: Đăng tin (Wizard NEED + Form OFFER) | F7: =IF($D7="","",IFERROR(COUNTIF(INDIRECT("'"&$D7&"'!$C$7:$C$500"),"?*"),0)) | G7: =IF($D7="","",IFERROR(COUNTIF(INDIRECT("'"&$D7&"'!$AO$7:$AO$500"),"Pass"),0)) | H7: =IF($D7="","",IFERROR(COUNTIF(INDIRECT("'"&$D7&"'!$AO$7:$AO$500"),"Fail"),0)) | I7: =IF($D7="","",IFERROR(COUNTIF(INDIRECT("'"&$D7&"'!$AO$7:$AO$500"),"Block"),0)) | J7: =IF($D7="","",IFERROR(COUNTIF(INDIRECT("'"&$D7&"'!$AO$7:$AO$500"),"N/A"),0)) | K7: =IF($D7="","",MAX(0,$F7-$G7-$H7-$I7-$J7)) | L7: =IF($D7="","",$G7+$H7+$I7+$J7) | M7: =IF($D7="","",IFERROR($L7/$F7,0)) | N7: =IF($D7="","",IFERROR($G7/$L7,0)) | O7: =IF($D7="","",IFERROR(COUNTIF(INDIRECT("'"&$D7&"'!$E$7:$E$500"),"High"),0)) | P7: =IF($D7="","",IFERROR(COUNTIF(INDIRECT("'"&$D7&"'!$E$7:$E$500"),"Medium"),0)) | Q7: =IF($D7="","",IFERROR(COUNTIF(INDIRECT("'"&$D7&"'!$E$7:$E$500"),"Low"),0)) | R7: =IF($D7="","",IFERROR(COUNTIF(INDIRECT("'"&$D7&"'!$D$7:$D$500"),"Functional"),0)) | S7: =IF($D7="","",IFERROR(COUNTIF(INDIRECT("'"&$D7&"'!$D$7:$D$500"),"UI"),0)) | T7: =IF($D7="","",IFERROR(COUNTIF(INDIRECT("'"&$D7&"'!$D$7:$D$500"),"Integration"),0)) | U7: =IF($D7="","",IFERROR(COUNTIF(INDIRECT("'"&$D7&"'!$D$7:$D$500"),"Database Test Case"),0)) | V7: =IF($D7="","",IFERROR(COUNTIF(INDIRECT("'"&$D7&"'!$J$7:$J$500"),"AI"),0)) | W7: =IF($D7="","",IFERROR(COUNTIF(INDIRECT("'"&$D7&"'!$J$7:$J$500"),"QC"),0)) | X7: =IF($D7="","",IFERROR(COUNTIF(INDIRECT("'"&$D7&"'!$L$7:$L$500"),"Yes"),0)) | Y7: =IF($D7="","",IFERROR(COUNTIF(INDIRECT("'"&$D7&"'!$AM$7:$AM$500"),"Yes"),0)) | Z7: =IF($D7="","",IFERROR(COUNTIF(INDIRECT("'"&$D7&"'!$AN$7:$AN$500"),"Pass"),0)) | AA7: =IF($D7="","",IFERROR(COUNTIF(INDIRECT("'"&$D7&"'!$K$7:$K$500"),"Reviewed"),0)) | AB7: =IF($D7="","",IFERROR(SUMPRODUCT((INDIRECT("'"&$D7&"'!$E$7:$E$500")="High")*(INDIRECT("'"&$D7&"'!$AO$7:$AO$500")<>"")),0)) | AC7: =IF($D7="","",IFERROR(SUMPRODUCT((INDIRECT("'"&$D7&"'!$E$7:$E$500")="Medium")*(INDIRECT("'"&$D7&"'!$AO$7:$AO$500")<>"")),0)) | AD7: =IF($D7="","",IFERROR(SUMPRODUCT((INDIRECT("'"&$D7&"'!$E$7:$E$500")="Low")*(INDIRECT("'"&$D7&"'!$AO$7:$AO$500")<>"")),0)) | AE7: =IF($D7="","",IFERROR(COUNTIF(INDIRECT("'"&$D7&"'!$P$7:$P$500"),"<>"),0)) | AF7: =IF($D7="","",IFERROR(COUNTIF(INDIRECT("'"&$D7&"'!$P$7:$P$500"),"Pass"),0)) | AG7: =IF($D7="","",IFERROR(COUNTIF(INDIRECT("'"&$D7&"'!$P$7:$P$500"),"Fail"),0)) | AH7: =IF($D7="","",IFERROR(COUNTIF(INDIRECT("'"&$D7&"'!$P$7:$P$500"),"Block"),0)) | AI7: =IF($D7="","",IFERROR(COUNTIF(INDIRECT("'"&$D7&"'!$P$7:$P$500"),"N/A"),0)) | AJ7: =IF($D7="","",IFERROR(COUNTIF(INDIRECT("'"&$D7&"'!$U$7:$U$500"),"<>"),0)) | AK7: =IF($D7="","",IFERROR(COUNTIF(INDIRECT("'"&$D7&"'!$U$7:$U$500"),"Pass"),0)) | AL7: =IF($D7="","",IFERROR(COUNTIF(INDIRECT("'"&$D7&"'!$U$7:$U$500"),"Fail"),0)) | AM7: =IF($D7="","",IFERROR(COUNTIF(INDIRECT("'"&$D7&"'!$U$7:$U$500"),"Block"),0)) | AN7: =IF($D7="","",IFERROR(COUNTIF(INDIRECT("'"&$D7&"'!$U$7:$U$500"),"N/A"),0)) | AO7: =IF($D7="","",IFERROR(COUNTIF(INDIRECT("'"&$D7&"'!$Z$7:$Z$500"),"<>"),0)) | AP7: =IF($D7="","",IFERROR(COUNTIF(INDIRECT("'"&$D7&"'!$Z$7:$Z$500"),"Pass"),0)) | AQ7: =IF($D7="","",IFERROR(COUNTIF(INDIRECT("'"&$D7&"'!$Z$7:$Z$500"),"Fail"),0)) | AR7: =IF($D7="","",IFERROR(COUNTIF(INDIRECT("'"&$D7&"'!$Z$7:$Z$500"),"Block"),0)) | AS7: =IF($D7="","",IFERROR(COUNTIF(INDIRECT("'"&$D7&"'!$Z$7:$Z$500"),"N/A"),0)) | AT7: =IF($D7="","",IFERROR(COUNTIF(INDIRECT("'"&$D7&"'!$AE$7:$AE$500"),"<>"),0)) | AU7: =IF($D7="","",IFERROR(COUNTIF(INDIRECT("'"&$D7&"'!$AE$7:$AE$500"),"Pass"),0)) | AV7: =IF($D7="","",IFERROR(COUNTIF(INDIRECT("'"&$D7&"'!$AE$7:$AE$500"),"Fail"),0)) | AW7: =IF($D7="","",IFERROR(COUNTIF(INDIRECT("'"&$D7&"'!$AE$7:$AE$500"),"Block"),0)) | AX7: =IF($D7="","",IFERROR(COUNTIF(INDIRECT("'"&$D7&"'!$AE$7:$AE$500"),"N/A"),0)) | AY7: =IF($D7="","",IFERROR(COUNTIF(INDIRECT("'"&$D7&"'!$AJ$7:$AJ$500"),"<>"),0)) | AZ7: =IF($D7="","",IFERROR(COUNTIF(INDIRECT("'"&$D7&"'!$AJ$7:$AJ$500"),"Pass"),0)) | BA7: =IF($D7="","",IFERROR(COUNTIF(INDIRECT("'"&$D7&"'!$AJ$7:$AJ$500"),"Fail"),0)) | BB7: =IF($D7="","",IFERROR(COUNTIF(INDIRECT("'"&$D7&"'!$AJ$7:$AJ$500"),"Block"),0)) | BC7: =IF($D7="","",IFERROR(COUNTIF(INDIRECT("'"&$D7&"'!$AJ$7:$AJ$500"),"N/A"),0))
B8: =IF($D8="","",ROW()-3) | C8: TC_05 | D8: Trang chủ | E8: Trang chủ | F8: =IF($D8="","",IFERROR(COUNTIF(INDIRECT("'"&$D8&"'!$C$7:$C$500"),"?*"),0)) | G8: =IF($D8="","",IFERROR(COUNTIF(INDIRECT("'"&$D8&"'!$AO$7:$AO$500"),"Pass"),0)) | H8: =IF($D8="","",IFERROR(COUNTIF(INDIRECT("'"&$D8&"'!$AO$7:$AO$500"),"Fail"),0)) | I8: =IF($D8="","",IFERROR(COUNTIF(INDIRECT("'"&$D8&"'!$AO$7:$AO$500"),"Block"),0)) | J8: =IF($D8="","",IFERROR(COUNTIF(INDIRECT("'"&$D8&"'!$AO$7:$AO$500"),"N/A"),0)) | K8: =IF($D8="","",MAX(0,$F8-$G8-$H8-$I8-$J8)) | L8: =IF($D8="","",$G8+$H8+$I8+$J8) | M8: =IF($D8="","",IFERROR($L8/$F8,0)) | N8: =IF($D8="","",IFERROR($G8/$L8,0)) | O8: =IF($D8="","",IFERROR(COUNTIF(INDIRECT("'"&$D8&"'!$E$7:$E$500"),"High"),0)) | P8: =IF($D8="","",IFERROR(COUNTIF(INDIRECT("'"&$D8&"'!$E$7:$E$500"),"Medium"),0)) | Q8: =IF($D8="","",IFERROR(COUNTIF(INDIRECT("'"&$D8&"'!$E$7:$E$500"),"Low"),0)) | R8: =IF($D8="","",IFERROR(COUNTIF(INDIRECT("'"&$D8&"'!$D$7:$D$500"),"Functional"),0)) | S8: =IF($D8="","",IFERROR(COUNTIF(INDIRECT("'"&$D8&"'!$D$7:$D$500"),"UI"),0)) | T8: =IF($D8="","",IFERROR(COUNTIF(INDIRECT("'"&$D8&"'!$D$7:$D$500"),"Integration"),0)) | U8: =IF($D8="","",IFERROR(COUNTIF(INDIRECT("'"&$D8&"'!$D$7:$D$500"),"Database Test Case"),0)) | V8: =IF($D8="","",IFERROR(COUNTIF(INDIRECT("'"&$D8&"'!$J$7:$J$500"),"AI"),0)) | W8: =IF($D8="","",IFERROR(COUNTIF(INDIRECT("'"&$D8&"'!$J$7:$J$500"),"QC"),0)) | X8: =IF($D8="","",IFERROR(COUNTIF(INDIRECT("'"&$D8&"'!$L$7:$L$500"),"Yes"),0)) | Y8: =IF($D8="","",IFERROR(COUNTIF(INDIRECT("'"&$D8&"'!$AM$7:$AM$500"),"Yes"),0)) | Z8: =IF($D8="","",IFERROR(COUNTIF(INDIRECT("'"&$D8&"'!$AN$7:$AN$500"),"Pass"),0)) | AA8: =IF($D8="","",IFERROR(COUNTIF(INDIRECT("'"&$D8&"'!$K$7:$K$500"),"Reviewed"),0)) | AB8: =IF($D8="","",IFERROR(SUMPRODUCT((INDIRECT("'"&$D8&"'!$E$7:$E$500")="High")*(INDIRECT("'"&$D8&"'!$AO$7:$AO$500")<>"")),0)) | AC8: =IF($D8="","",IFERROR(SUMPRODUCT((INDIRECT("'"&$D8&"'!$E$7:$E$500")="Medium")*(INDIRECT("'"&$D8&"'!$AO$7:$AO$500")<>"")),0)) | AD8: =IF($D8="","",IFERROR(SUMPRODUCT((INDIRECT("'"&$D8&"'!$E$7:$E$500")="Low")*(INDIRECT("'"&$D8&"'!$AO$7:$AO$500")<>"")),0)) | AE8: =IF($D8="","",IFERROR(COUNTIF(INDIRECT("'"&$D8&"'!$P$7:$P$500"),"<>"),0)) | AF8: =IF($D8="","",IFERROR(COUNTIF(INDIRECT("'"&$D8&"'!$P$7:$P$500"),"Pass"),0)) | AG8: =IF($D8="","",IFERROR(COUNTIF(INDIRECT("'"&$D8&"'!$P$7:$P$500"),"Fail"),0)) | AH8: =IF($D8="","",IFERROR(COUNTIF(INDIRECT("'"&$D8&"'!$P$7:$P$500"),"Block"),0)) | AI8: =IF($D8="","",IFERROR(COUNTIF(INDIRECT("'"&$D8&"'!$P$7:$P$500"),"N/A"),0)) | AJ8: =IF($D8="","",IFERROR(COUNTIF(INDIRECT("'"&$D8&"'!$U$7:$U$500"),"<>"),0)) | AK8: =IF($D8="","",IFERROR(COUNTIF(INDIRECT("'"&$D8&"'!$U$7:$U$500"),"Pass"),0)) | AL8: =IF($D8="","",IFERROR(COUNTIF(INDIRECT("'"&$D8&"'!$U$7:$U$500"),"Fail"),0)) | AM8: =IF($D8="","",IFERROR(COUNTIF(INDIRECT("'"&$D8&"'!$U$7:$U$500"),"Block"),0)) | AN8: =IF($D8="","",IFERROR(COUNTIF(INDIRECT("'"&$D8&"'!$U$7:$U$500"),"N/A"),0)) | AO8: =IF($D8="","",IFERROR(COUNTIF(INDIRECT("'"&$D8&"'!$Z$7:$Z$500"),"<>"),0)) | AP8: =IF($D8="","",IFERROR(COUNTIF(INDIRECT("'"&$D8&"'!$Z$7:$Z$500"),"Pass"),0)) | AQ8: =IF($D8="","",IFERROR(COUNTIF(INDIRECT("'"&$D8&"'!$Z$7:$Z$500"),"Fail"),0)) | AR8: =IF($D8="","",IFERROR(COUNTIF(INDIRECT("'"&$D8&"'!$Z$7:$Z$500"),"Block"),0)) | AS8: =IF($D8="","",IFERROR(COUNTIF(INDIRECT("'"&$D8&"'!$Z$7:$Z$500"),"N/A"),0)) | AT8: =IF($D8="","",IFERROR(COUNTIF(INDIRECT("'"&$D8&"'!$AE$7:$AE$500"),"<>"),0)) | AU8: =IF($D8="","",IFERROR(COUNTIF(INDIRECT("'"&$D8&"'!$AE$7:$AE$500"),"Pass"),0)) | AV8: =IF($D8="","",IFERROR(COUNTIF(INDIRECT("'"&$D8&"'!$AE$7:$AE$500"),"Fail"),0)) | AW8: =IF($D8="","",IFERROR(COUNTIF(INDIRECT("'"&$D8&"'!$AE$7:$AE$500"),"Block"),0)) | AX8: =IF($D8="","",IFERROR(COUNTIF(INDIRECT("'"&$D8&"'!$AE$7:$AE$500"),"N/A"),0)) | AY8: =IF($D8="","",IFERROR(COUNTIF(INDIRECT("'"&$D8&"'!$AJ$7:$AJ$500"),"<>"),0)) | AZ8: =IF($D8="","",IFERROR(COUNTIF(INDIRECT("'"&$D8&"'!$AJ$7:$AJ$500"),"Pass"),0)) | BA8: =IF($D8="","",IFERROR(COUNTIF(INDIRECT("'"&$D8&"'!$AJ$7:$AJ$500"),"Fail"),0)) | BB8: =IF($D8="","",IFERROR(COUNTIF(INDIRECT("'"&$D8&"'!$AJ$7:$AJ$500"),"Block"),0)) | BC8: =IF($D8="","",IFERROR(COUNTIF(INDIRECT("'"&$D8&"'!$AJ$7:$AJ$500"),"N/A"),0))
B9: =IF($D9="","",ROW()-3) | C9: TC_06 | D9: Bảng tin & Chi tiết tin | E9: Bảng tin & Chi tiết tin | F9: =IF($D9="","",IFERROR(COUNTIF(INDIRECT("'"&$D9&"'!$C$7:$C$500"),"?*"),0)) | G9: =IF($D9="","",IFERROR(COUNTIF(INDIRECT("'"&$D9&"'!$AO$7:$AO$500"),"Pass"),0)) | H9: =IF($D9="","",IFERROR(COUNTIF(INDIRECT("'"&$D9&"'!$AO$7:$AO$500"),"Fail"),0)) | I9: =IF($D9="","",IFERROR(COUNTIF(INDIRECT("'"&$D9&"'!$AO$7:$AO$500"),"Block"),0)) | J9: =IF($D9="","",IFERROR(COUNTIF(INDIRECT("'"&$D9&"'!$AO$7:$AO$500"),"N/A"),0)) | K9: =IF($D9="","",MAX(0,$F9-$G9-$H9-$I9-$J9)) | L9: =IF($D9="","",$G9+$H9+$I9+$J9) | M9: =IF($D9="","",IFERROR($L9/$F9,0)) | N9: =IF($D9="","",IFERROR($G9/$L9,0)) | O9: =IF($D9="","",IFERROR(COUNTIF(INDIRECT("'"&$D9&"'!$E$7:$E$500"),"High"),0)) | P9: =IF($D9="","",IFERROR(COUNTIF(INDIRECT("'"&$D9&"'!$E$7:$E$500"),"Medium"),0)) | Q9: =IF($D9="","",IFERROR(COUNTIF(INDIRECT("'"&$D9&"'!$E$7:$E$500"),"Low"),0)) | R9: =IF($D9="","",IFERROR(COUNTIF(INDIRECT("'"&$D9&"'!$D$7:$D$500"),"Functional"),0)) | S9: =IF($D9="","",IFERROR(COUNTIF(INDIRECT("'"&$D9&"'!$D$7:$D$500"),"UI"),0)) | T9: =IF($D9="","",IFERROR(COUNTIF(INDIRECT("'"&$D9&"'!$D$7:$D$500"),"Integration"),0)) | U9: =IF($D9="","",IFERROR(COUNTIF(INDIRECT("'"&$D9&"'!$D$7:$D$500"),"Database Test Case"),0)) | V9: =IF($D9="","",IFERROR(COUNTIF(INDIRECT("'"&$D9&"'!$J$7:$J$500"),"AI"),0)) | W9: =IF($D9="","",IFERROR(COUNTIF(INDIRECT("'"&$D9&"'!$J$7:$J$500"),"QC"),0)) | X9: =IF($D9="","",IFERROR(COUNTIF(INDIRECT("'"&$D9&"'!$L$7:$L$500"),"Yes"),0)) | Y9: =IF($D9="","",IFERROR(COUNTIF(INDIRECT("'"&$D9&"'!$AM$7:$AM$500"),"Yes"),0)) | Z9: =IF($D9="","",IFERROR(COUNTIF(INDIRECT("'"&$D9&"'!$AN$7:$AN$500"),"Pass"),0)) | AA9: =IF($D9="","",IFERROR(COUNTIF(INDIRECT("'"&$D9&"'!$K$7:$K$500"),"Reviewed"),0)) | AB9: =IF($D9="","",IFERROR(SUMPRODUCT((INDIRECT("'"&$D9&"'!$E$7:$E$500")="High")*(INDIRECT("'"&$D9&"'!$AO$7:$AO$500")<>"")),0)) | AC9: =IF($D9="","",IFERROR(SUMPRODUCT((INDIRECT("'"&$D9&"'!$E$7:$E$500")="Medium")*(INDIRECT("'"&$D9&"'!$AO$7:$AO$500")<>"")),0)) | AD9: =IF($D9="","",IFERROR(SUMPRODUCT((INDIRECT("'"&$D9&"'!$E$7:$E$500")="Low")*(INDIRECT("'"&$D9&"'!$AO$7:$AO$500")<>"")),0)) | AE9: =IF($D9="","",IFERROR(COUNTIF(INDIRECT("'"&$D9&"'!$P$7:$P$500"),"<>"),0)) | AF9: =IF($D9="","",IFERROR(COUNTIF(INDIRECT("'"&$D9&"'!$P$7:$P$500"),"Pass"),0)) | AG9: =IF($D9="","",IFERROR(COUNTIF(INDIRECT("'"&$D9&"'!$P$7:$P$500"),"Fail"),0)) | AH9: =IF($D9="","",IFERROR(COUNTIF(INDIRECT("'"&$D9&"'!$P$7:$P$500"),"Block"),0)) | AI9: =IF($D9="","",IFERROR(COUNTIF(INDIRECT("'"&$D9&"'!$P$7:$P$500"),"N/A"),0)) | AJ9: =IF($D9="","",IFERROR(COUNTIF(INDIRECT("'"&$D9&"'!$U$7:$U$500"),"<>"),0)) | AK9: =IF($D9="","",IFERROR(COUNTIF(INDIRECT("'"&$D9&"'!$U$7:$U$500"),"Pass"),0)) | AL9: =IF($D9="","",IFERROR(COUNTIF(INDIRECT("'"&$D9&"'!$U$7:$U$500"),"Fail"),0)) | AM9: =IF($D9="","",IFERROR(COUNTIF(INDIRECT("'"&$D9&"'!$U$7:$U$500"),"Block"),0)) | AN9: =IF($D9="","",IFERROR(COUNTIF(INDIRECT("'"&$D9&"'!$U$7:$U$500"),"N/A"),0)) | AO9: =IF($D9="","",IFERROR(COUNTIF(INDIRECT("'"&$D9&"'!$Z$7:$Z$500"),"<>"),0)) | AP9: =IF($D9="","",IFERROR(COUNTIF(INDIRECT("'"&$D9&"'!$Z$7:$Z$500"),"Pass"),0)) | AQ9: =IF($D9="","",IFERROR(COUNTIF(INDIRECT("'"&$D9&"'!$Z$7:$Z$500"),"Fail"),0)) | AR9: =IF($D9="","",IFERROR(COUNTIF(INDIRECT("'"&$D9&"'!$Z$7:$Z$500"),"Block"),0)) | AS9: =IF($D9="","",IFERROR(COUNTIF(INDIRECT("'"&$D9&"'!$Z$7:$Z$500"),"N/A"),0)) | AT9: =IF($D9="","",IFERROR(COUNTIF(INDIRECT("'"&$D9&"'!$AE$7:$AE$500"),"<>"),0)) | AU9: =IF($D9="","",IFERROR(COUNTIF(INDIRECT("'"&$D9&"'!$AE$7:$AE$500"),"Pass"),0)) | AV9: =IF($D9="","",IFERROR(COUNTIF(INDIRECT("'"&$D9&"'!$AE$7:$AE$500"),"Fail"),0)) | AW9: =IF($D9="","",IFERROR(COUNTIF(INDIRECT("'"&$D9&"'!$AE$7:$AE$500"),"Block"),0)) | AX9: =IF($D9="","",IFERROR(COUNTIF(INDIRECT("'"&$D9&"'!$AE$7:$AE$500"),"N/A"),0)) | AY9: =IF($D9="","",IFERROR(COUNTIF(INDIRECT("'"&$D9&"'!$AJ$7:$AJ$500"),"<>"),0)) | AZ9: =IF($D9="","",IFERROR(COUNTIF(INDIRECT("'"&$D9&"'!$AJ$7:$AJ$500"),"Pass"),0)) | BA9: =IF($D9="","",IFERROR(COUNTIF(INDIRECT("'"&$D9&"'!$AJ$7:$AJ$500"),"Fail"),0)) | BB9: =IF($D9="","",IFERROR(COUNTIF(INDIRECT("'"&$D9&"'!$AJ$7:$AJ$500"),"Block"),0)) | BC9: =IF($D9="","",IFERROR(COUNTIF(INDIRECT("'"&$D9&"'!$AJ$7:$AJ$500"),"N/A"),0))
B10: =IF($D10="","",ROW()-3) | C10: TC_07 | D10: Theo dõi đơn | E10: Theo dõi đơn (3 vai trò) | F10: =IF($D10="","",IFERROR(COUNTIF(INDIRECT("'"&$D10&"'!$C$7:$C$500"),"?*"),0)) | G10: =IF($D10="","",IFERROR(COUNTIF(INDIRECT("'"&$D10&"'!$AO$7:$AO$500"),"Pass"),0)) | H10: =IF($D10="","",IFERROR(COUNTIF(INDIRECT("'"&$D10&"'!$AO$7:$AO$500"),"Fail"),0)) | I10: =IF($D10="","",IFERROR(COUNTIF(INDIRECT("'"&$D10&"'!$AO$7:$AO$500"),"Block"),0)) | J10: =IF($D10="","",IFERROR(COUNTIF(INDIRECT("'"&$D10&"'!$AO$7:$AO$500"),"N/A"),0)) | K10: =IF($D10="","",MAX(0,$F10-$G10-$H10-$I10-$J10)) | L10: =IF($D10="","",$G10+$H10+$I10+$J10) | M10: =IF($D10="","",IFERROR($L10/$F10,0)) | N10: =IF($D10="","",IFERROR($G10/$L10,0)) | O10: =IF($D10="","",IFERROR(COUNTIF(INDIRECT("'"&$D10&"'!$E$7:$E$500"),"High"),0)) | P10: =IF($D10="","",IFERROR(COUNTIF(INDIRECT("'"&$D10&"'!$E$7:$E$500"),"Medium"),0)) | Q10: =IF($D10="","",IFERROR(COUNTIF(INDIRECT("'"&$D10&"'!$E$7:$E$500"),"Low"),0)) | R10: =IF($D10="","",IFERROR(COUNTIF(INDIRECT("'"&$D10&"'!$D$7:$D$500"),"Functional"),0)) | S10: =IF($D10="","",IFERROR(COUNTIF(INDIRECT("'"&$D10&"'!$D$7:$D$500"),"UI"),0)) | T10: =IF($D10="","",IFERROR(COUNTIF(INDIRECT("'"&$D10&"'!$D$7:$D$500"),"Integration"),0)) | U10: =IF($D10="","",IFERROR(COUNTIF(INDIRECT("'"&$D10&"'!$D$7:$D$500"),"Database Test Case"),0)) | V10: =IF($D10="","",IFERROR(COUNTIF(INDIRECT("'"&$D10&"'!$J$7:$J$500"),"AI"),0)) | W10: =IF($D10="","",IFERROR(COUNTIF(INDIRECT("'"&$D10&"'!$J$7:$J$500"),"QC"),0)) | X10: =IF($D10="","",IFERROR(COUNTIF(INDIRECT("'"&$D10&"'!$L$7:$L$500"),"Yes"),0)) | Y10: =IF($D10="","",IFERROR(COUNTIF(INDIRECT("'"&$D10&"'!$AM$7:$AM$500"),"Yes"),0)) | Z10: =IF($D10="","",IFERROR(COUNTIF(INDIRECT("'"&$D10&"'!$AN$7:$AN$500"),"Pass"),0)) | AA10: =IF($D10="","",IFERROR(COUNTIF(INDIRECT("'"&$D10&"'!$K$7:$K$500"),"Reviewed"),0)) | AB10: =IF($D10="","",IFERROR(SUMPRODUCT((INDIRECT("'"&$D10&"'!$E$7:$E$500")="High")*(INDIRECT("'"&$D10&"'!$AO$7:$AO$500")<>"")),0)) | AC10: =IF($D10="","",IFERROR(SUMPRODUCT((INDIRECT("'"&$D10&"'!$E$7:$E$500")="Medium")*(INDIRECT("'"&$D10&"'!$AO$7:$AO$500")<>"")),0)) | AD10: =IF($D10="","",IFERROR(SUMPRODUCT((INDIRECT("'"&$D10&"'!$E$7:$E$500")="Low")*(INDIRECT("'"&$D10&"'!$AO$7:$AO$500")<>"")),0)) | AE10: =IF($D10="","",IFERROR(COUNTIF(INDIRECT("'"&$D10&"'!$P$7:$P$500"),"<>"),0)) | AF10: =IF($D10="","",IFERROR(COUNTIF(INDIRECT("'"&$D10&"'!$P$7:$P$500"),"Pass"),0)) | AG10: =IF($D10="","",IFERROR(COUNTIF(INDIRECT("'"&$D10&"'!$P$7:$P$500"),"Fail"),0)) | AH10: =IF($D10="","",IFERROR(COUNTIF(INDIRECT("'"&$D10&"'!$P$7:$P$500"),"Block"),0)) | AI10: =IF($D10="","",IFERROR(COUNTIF(INDIRECT("'"&$D10&"'!$P$7:$P$500"),"N/A"),0)) | AJ10: =IF($D10="","",IFERROR(COUNTIF(INDIRECT("'"&$D10&"'!$U$7:$U$500"),"<>"),0)) | AK10: =IF($D10="","",IFERROR(COUNTIF(INDIRECT("'"&$D10&"'!$U$7:$U$500"),"Pass"),0)) | AL10: =IF($D10="","",IFERROR(COUNTIF(INDIRECT("'"&$D10&"'!$U$7:$U$500"),"Fail"),0)) | AM10: =IF($D10="","",IFERROR(COUNTIF(INDIRECT("'"&$D10&"'!$U$7:$U$500"),"Block"),0)) | AN10: =IF($D10="","",IFERROR(COUNTIF(INDIRECT("'"&$D10&"'!$U$7:$U$500"),"N/A"),0)) | AO10: =IF($D10="","",IFERROR(COUNTIF(INDIRECT("'"&$D10&"'!$Z$7:$Z$500"),"<>"),0)) | AP10: =IF($D10="","",IFERROR(COUNTIF(INDIRECT("'"&$D10&"'!$Z$7:$Z$500"),"Pass"),0)) | AQ10: =IF($D10="","",IFERROR(COUNTIF(INDIRECT("'"&$D10&"'!$Z$7:$Z$500"),"Fail"),0)) | AR10: =IF($D10="","",IFERROR(COUNTIF(INDIRECT("'"&$D10&"'!$Z$7:$Z$500"),"Block"),0)) | AS10: =IF($D10="","",IFERROR(COUNTIF(INDIRECT("'"&$D10&"'!$Z$7:$Z$500"),"N/A"),0)) | AT10: =IF($D10="","",IFERROR(COUNTIF(INDIRECT("'"&$D10&"'!$AE$7:$AE$500"),"<>"),0)) | AU10: =IF($D10="","",IFERROR(COUNTIF(INDIRECT("'"&$D10&"'!$AE$7:$AE$500"),"Pass"),0)) | AV10: =IF($D10="","",IFERROR(COUNTIF(INDIRECT("'"&$D10&"'!$AE$7:$AE$500"),"Fail"),0)) | AW10: =IF($D10="","",IFERROR(COUNTIF(INDIRECT("'"&$D10&"'!$AE$7:$AE$500"),"Block"),0)) | AX10: =IF($D10="","",IFERROR(COUNTIF(INDIRECT("'"&$D10&"'!$AE$7:$AE$500"),"N/A"),0)) | AY10: =IF($D10="","",IFERROR(COUNTIF(INDIRECT("'"&$D10&"'!$AJ$7:$AJ$500"),"<>"),0)) | AZ10: =IF($D10="","",IFERROR(COUNTIF(INDIRECT("'"&$D10&"'!$AJ$7:$AJ$500"),"Pass"),0)) | BA10: =IF($D10="","",IFERROR(COUNTIF(INDIRECT("'"&$D10&"'!$AJ$7:$AJ$500"),"Fail"),0)) | BB10: =IF($D10="","",IFERROR(COUNTIF(INDIRECT("'"&$D10&"'!$AJ$7:$AJ$500"),"Block"),0)) | BC10: =IF($D10="","",IFERROR(COUNTIF(INDIRECT("'"&$D10&"'!$AJ$7:$AJ$500"),"N/A"),0))
B11: =IF($D11="","",ROW()-3) | C11: TC_08 | D11: Huỷ đơn | E11: Huỷ đơn | F11: =IF($D11="","",IFERROR(COUNTIF(INDIRECT("'"&$D11&"'!$C$7:$C$500"),"?*"),0)) | G11: =IF($D11="","",IFERROR(COUNTIF(INDIRECT("'"&$D11&"'!$AO$7:$AO$500"),"Pass"),0)) | H11: =IF($D11="","",IFERROR(COUNTIF(INDIRECT("'"&$D11&"'!$AO$7:$AO$500"),"Fail"),0)) | I11: =IF($D11="","",IFERROR(COUNTIF(INDIRECT("'"&$D11&"'!$AO$7:$AO$500"),"Block"),0)) | J11: =IF($D11="","",IFERROR(COUNTIF(INDIRECT("'"&$D11&"'!$AO$7:$AO$500"),"N/A"),0)) | K11: =IF($D11="","",MAX(0,$F11-$G11-$H11-$I11-$J11)) | L11: =IF($D11="","",$G11+$H11+$I11+$J11) | M11: =IF($D11="","",IFERROR($L11/$F11,0)) | N11: =IF($D11="","",IFERROR($G11/$L11,0)) | O11: =IF($D11="","",IFERROR(COUNTIF(INDIRECT("'"&$D11&"'!$E$7:$E$500"),"High"),0)) | P11: =IF($D11="","",IFERROR(COUNTIF(INDIRECT("'"&$D11&"'!$E$7:$E$500"),"Medium"),0)) | Q11: =IF($D11="","",IFERROR(COUNTIF(INDIRECT("'"&$D11&"'!$E$7:$E$500"),"Low"),0)) | R11: =IF($D11="","",IFERROR(COUNTIF(INDIRECT("'"&$D11&"'!$D$7:$D$500"),"Functional"),0)) | S11: =IF($D11="","",IFERROR(COUNTIF(INDIRECT("'"&$D11&"'!$D$7:$D$500"),"UI"),0)) | T11: =IF($D11="","",IFERROR(COUNTIF(INDIRECT("'"&$D11&"'!$D$7:$D$500"),"Integration"),0)) | U11: =IF($D11="","",IFERROR(COUNTIF(INDIRECT("'"&$D11&"'!$D$7:$D$500"),"Database Test Case"),0)) | V11: =IF($D11="","",IFERROR(COUNTIF(INDIRECT("'"&$D11&"'!$J$7:$J$500"),"AI"),0)) | W11: =IF($D11="","",IFERROR(COUNTIF(INDIRECT("'"&$D11&"'!$J$7:$J$500"),"QC"),0)) | X11: =IF($D11="","",IFERROR(COUNTIF(INDIRECT("'"&$D11&"'!$L$7:$L$500"),"Yes"),0)) | Y11: =IF($D11="","",IFERROR(COUNTIF(INDIRECT("'"&$D11&"'!$AM$7:$AM$500"),"Yes"),0)) | Z11: =IF($D11="","",IFERROR(COUNTIF(INDIRECT("'"&$D11&"'!$AN$7:$AN$500"),"Pass"),0)) | AA11: =IF($D11="","",IFERROR(COUNTIF(INDIRECT("'"&$D11&"'!$K$7:$K$500"),"Reviewed"),0)) | AB11: =IF($D11="","",IFERROR(SUMPRODUCT((INDIRECT("'"&$D11&"'!$E$7:$E$500")="High")*(INDIRECT("'"&$D11&"'!$AO$7:$AO$500")<>"")),0)) | AC11: =IF($D11="","",IFERROR(SUMPRODUCT((INDIRECT("'"&$D11&"'!$E$7:$E$500")="Medium")*(INDIRECT("'"&$D11&"'!$AO$7:$AO$500")<>"")),0)) | AD11: =IF($D11="","",IFERROR(SUMPRODUCT((INDIRECT("'"&$D11&"'!$E$7:$E$500")="Low")*(INDIRECT("'"&$D11&"'!$AO$7:$AO$500")<>"")),0)) | AE11: =IF($D11="","",IFERROR(COUNTIF(INDIRECT("'"&$D11&"'!$P$7:$P$500"),"<>"),0)) | AF11: =IF($D11="","",IFERROR(COUNTIF(INDIRECT("'"&$D11&"'!$P$7:$P$500"),"Pass"),0)) | AG11: =IF($D11="","",IFERROR(COUNTIF(INDIRECT("'"&$D11&"'!$P$7:$P$500"),"Fail"),0)) | AH11: =IF($D11="","",IFERROR(COUNTIF(INDIRECT("'"&$D11&"'!$P$7:$P$500"),"Block"),0)) | AI11: =IF($D11="","",IFERROR(COUNTIF(INDIRECT("'"&$D11&"'!$P$7:$P$500"),"N/A"),0)) | AJ11: =IF($D11="","",IFERROR(COUNTIF(INDIRECT("'"&$D11&"'!$U$7:$U$500"),"<>"),0)) | AK11: =IF($D11="","",IFERROR(COUNTIF(INDIRECT("'"&$D11&"'!$U$7:$U$500"),"Pass"),0)) | AL11: =IF($D11="","",IFERROR(COUNTIF(INDIRECT("'"&$D11&"'!$U$7:$U$500"),"Fail"),0)) | AM11: =IF($D11="","",IFERROR(COUNTIF(INDIRECT("'"&$D11&"'!$U$7:$U$500"),"Block"),0)) | AN11: =IF($D11="","",IFERROR(COUNTIF(INDIRECT("'"&$D11&"'!$U$7:$U$500"),"N/A"),0)) | AO11: =IF($D11="","",IFERROR(COUNTIF(INDIRECT("'"&$D11&"'!$Z$7:$Z$500"),"<>"),0)) | AP11: =IF($D11="","",IFERROR(COUNTIF(INDIRECT("'"&$D11&"'!$Z$7:$Z$500"),"Pass"),0)) | AQ11: =IF($D11="","",IFERROR(COUNTIF(INDIRECT("'"&$D11&"'!$Z$7:$Z$500"),"Fail"),0)) | AR11: =IF($D11="","",IFERROR(COUNTIF(INDIRECT("'"&$D11&"'!$Z$7:$Z$500"),"Block"),0)) | AS11: =IF($D11="","",IFERROR(COUNTIF(INDIRECT("'"&$D11&"'!$Z$7:$Z$500"),"N/A"),0)) | AT11: =IF($D11="","",IFERROR(COUNTIF(INDIRECT("'"&$D11&"'!$AE$7:$AE$500"),"<>"),0)) | AU11: =IF($D11="","",IFERROR(COUNTIF(INDIRECT("'"&$D11&"'!$AE$7:$AE$500"),"Pass"),0)) | AV11: =IF($D11="","",IFERROR(COUNTIF(INDIRECT("'"&$D11&"'!$AE$7:$AE$500"),"Fail"),0)) | AW11: =IF($D11="","",IFERROR(COUNTIF(INDIRECT("'"&$D11&"'!$AE$7:$AE$500"),"Block"),0)) | AX11: =IF($D11="","",IFERROR(COUNTIF(INDIRECT("'"&$D11&"'!$AE$7:$AE$500"),"N/A"),0)) | AY11: =IF($D11="","",IFERROR(COUNTIF(INDIRECT("'"&$D11&"'!$AJ$7:$AJ$500"),"<>"),0)) | AZ11: =IF($D11="","",IFERROR(COUNTIF(INDIRECT("'"&$D11&"'!$AJ$7:$AJ$500"),"Pass"),0)) | BA11: =IF($D11="","",IFERROR(COUNTIF(INDIRECT("'"&$D11&"'!$AJ$7:$AJ$500"),"Fail"),0)) | BB11: =IF($D11="","",IFERROR(COUNTIF(INDIRECT("'"&$D11&"'!$AJ$7:$AJ$500"),"Block"),0)) | BC11: =IF($D11="","",IFERROR(COUNTIF(INDIRECT("'"&$D11&"'!$AJ$7:$AJ$500"),"N/A"),0))
B12: =IF($D12="","",ROW()-3) | C12: TC_09 | D12: Tặng quà | E12: Tặng quà | F12: =IF($D12="","",IFERROR(COUNTIF(INDIRECT("'"&$D12&"'!$C$7:$C$500"),"?*"),0)) | G12: =IF($D12="","",IFERROR(COUNTIF(INDIRECT("'"&$D12&"'!$AO$7:$AO$500"),"Pass"),0)) | H12: =IF($D12="","",IFERROR(COUNTIF(INDIRECT("'"&$D12&"'!$AO$7:$AO$500"),"Fail"),0)) | I12: =IF($D12="","",IFERROR(COUNTIF(INDIRECT("'"&$D12&"'!$AO$7:$AO$500"),"Block"),0)) | J12: =IF($D12="","",IFERROR(COUNTIF(INDIRECT("'"&$D12&"'!$AO$7:$AO$500"),"N/A"),0)) | K12: =IF($D12="","",MAX(0,$F12-$G12-$H12-$I12-$J12)) | L12: =IF($D12="","",$G12+$H12+$I12+$J12) | M12: =IF($D12="","",IFERROR($L12/$F12,0)) | N12: =IF($D12="","",IFERROR($G12/$L12,0)) | O12: =IF($D12="","",IFERROR(COUNTIF(INDIRECT("'"&$D12&"'!$E$7:$E$500"),"High"),0)) | P12: =IF($D12="","",IFERROR(COUNTIF(INDIRECT("'"&$D12&"'!$E$7:$E$500"),"Medium"),0)) | Q12: =IF($D12="","",IFERROR(COUNTIF(INDIRECT("'"&$D12&"'!$E$7:$E$500"),"Low"),0)) | R12: =IF($D12="","",IFERROR(COUNTIF(INDIRECT("'"&$D12&"'!$D$7:$D$500"),"Functional"),0)) | S12: =IF($D12="","",IFERROR(COUNTIF(INDIRECT("'"&$D12&"'!$D$7:$D$500"),"UI"),0)) | T12: =IF($D12="","",IFERROR(COUNTIF(INDIRECT("'"&$D12&"'!$D$7:$D$500"),"Integration"),0)) | U12: =IF($D12="","",IFERROR(COUNTIF(INDIRECT("'"&$D12&"'!$D$7:$D$500"),"Database Test Case"),0)) | V12: =IF($D12="","",IFERROR(COUNTIF(INDIRECT("'"&$D12&"'!$J$7:$J$500"),"AI"),0)) | W12: =IF($D12="","",IFERROR(COUNTIF(INDIRECT("'"&$D12&"'!$J$7:$J$500"),"QC"),0)) | X12: =IF($D12="","",IFERROR(COUNTIF(INDIRECT("'"&$D12&"'!$L$7:$L$500"),"Yes"),0)) | Y12: =IF($D12="","",IFERROR(COUNTIF(INDIRECT("'"&$D12&"'!$AM$7:$AM$500"),"Yes"),0)) | Z12: =IF($D12="","",IFERROR(COUNTIF(INDIRECT("'"&$D12&"'!$AN$7:$AN$500"),"Pass"),0)) | AA12: =IF($D12="","",IFERROR(COUNTIF(INDIRECT("'"&$D12&"'!$K$7:$K$500"),"Reviewed"),0)) | AB12: =IF($D12="","",IFERROR(SUMPRODUCT((INDIRECT("'"&$D12&"'!$E$7:$E$500")="High")*(INDIRECT("'"&$D12&"'!$AO$7:$AO$500")<>"")),0)) | AC12: =IF($D12="","",IFERROR(SUMPRODUCT((INDIRECT("'"&$D12&"'!$E$7:$E$500")="Medium")*(INDIRECT("'"&$D12&"'!$AO$7:$AO$500")<>"")),0)) | AD12: =IF($D12="","",IFERROR(SUMPRODUCT((INDIRECT("'"&$D12&"'!$E$7:$E$500")="Low")*(INDIRECT("'"&$D12&"'!$AO$7:$AO$500")<>"")),0)) | AE12: =IF($D12="","",IFERROR(COUNTIF(INDIRECT("'"&$D12&"'!$P$7:$P$500"),"<>"),0)) | AF12: =IF($D12="","",IFERROR(COUNTIF(INDIRECT("'"&$D12&"'!$P$7:$P$500"),"Pass"),0)) | AG12: =IF($D12="","",IFERROR(COUNTIF(INDIRECT("'"&$D12&"'!$P$7:$P$500"),"Fail"),0)) | AH12: =IF($D12="","",IFERROR(COUNTIF(INDIRECT("'"&$D12&"'!$P$7:$P$500"),"Block"),0)) | AI12: =IF($D12="","",IFERROR(COUNTIF(INDIRECT("'"&$D12&"'!$P$7:$P$500"),"N/A"),0)) | AJ12: =IF($D12="","",IFERROR(COUNTIF(INDIRECT("'"&$D12&"'!$U$7:$U$500"),"<>"),0)) | AK12: =IF($D12="","",IFERROR(COUNTIF(INDIRECT("'"&$D12&"'!$U$7:$U$500"),"Pass"),0)) | AL12: =IF($D12="","",IFERROR(COUNTIF(INDIRECT("'"&$D12&"'!$U$7:$U$500"),"Fail"),0)) | AM12: =IF($D12="","",IFERROR(COUNTIF(INDIRECT("'"&$D12&"'!$U$7:$U$500"),"Block"),0)) | AN12: =IF($D12="","",IFERROR(COUNTIF(INDIRECT("'"&$D12&"'!$U$7:$U$500"),"N/A"),0)) | AO12: =IF($D12="","",IFERROR(COUNTIF(INDIRECT("'"&$D12&"'!$Z$7:$Z$500"),"<>"),0)) | AP12: =IF($D12="","",IFERROR(COUNTIF(INDIRECT("'"&$D12&"'!$Z$7:$Z$500"),"Pass"),0)) | AQ12: =IF($D12="","",IFERROR(COUNTIF(INDIRECT("'"&$D12&"'!$Z$7:$Z$500"),"Fail"),0)) | AR12: =IF($D12="","",IFERROR(COUNTIF(INDIRECT("'"&$D12&"'!$Z$7:$Z$500"),"Block"),0)) | AS12: =IF($D12="","",IFERROR(COUNTIF(INDIRECT("'"&$D12&"'!$Z$7:$Z$500"),"N/A"),0)) | AT12: =IF($D12="","",IFERROR(COUNTIF(INDIRECT("'"&$D12&"'!$AE$7:$AE$500"),"<>"),0)) | AU12: =IF($D12="","",IFERROR(COUNTIF(INDIRECT("'"&$D12&"'!$AE$7:$AE$500"),"Pass"),0)) | AV12: =IF($D12="","",IFERROR(COUNTIF(INDIRECT("'"&$D12&"'!$AE$7:$AE$500"),"Fail"),0)) | AW12: =IF($D12="","",IFERROR(COUNTIF(INDIRECT("'"&$D12&"'!$AE$7:$AE$500"),"Block"),0)) | AX12: =IF($D12="","",IFERROR(COUNTIF(INDIRECT("'"&$D12&"'!$AE$7:$AE$500"),"N/A"),0)) | AY12: =IF($D12="","",IFERROR(COUNTIF(INDIRECT("'"&$D12&"'!$AJ$7:$AJ$500"),"<>"),0)) | AZ12: =IF($D12="","",IFERROR(COUNTIF(INDIRECT("'"&$D12&"'!$AJ$7:$AJ$500"),"Pass"),0)) | BA12: =IF($D12="","",IFERROR(COUNTIF(INDIRECT("'"&$D12&"'!$AJ$7:$AJ$500"),"Fail"),0)) | BB12: =IF($D12="","",IFERROR(COUNTIF(INDIRECT("'"&$D12&"'!$AJ$7:$AJ$500"),"Block"),0)) | BC12: =IF($D12="","",IFERROR(COUNTIF(INDIRECT("'"&$D12&"'!$AJ$7:$AJ$500"),"N/A"),0))
B13: =IF($D13="","",ROW()-3) | F13: =IF($D13="","",IFERROR(COUNTIF(INDIRECT("'"&$D13&"'!$C$7:$C$500"),"?*"),0)) | G13: =IF($D13="","",IFERROR(COUNTIF(INDIRECT("'"&$D13&"'!$AO$7:$AO$500"),"Pass"),0)) | H13: =IF($D13="","",IFERROR(COUNTIF(INDIRECT("'"&$D13&"'!$AO$7:$AO$500"),"Fail"),0)) | I13: =IF($D13="","",IFERROR(COUNTIF(INDIRECT("'"&$D13&"'!$AO$7:$AO$500"),"Block"),0)) | J13: =IF($D13="","",IFERROR(COUNTIF(INDIRECT("'"&$D13&"'!$AO$7:$AO$500"),"N/A"),0)) | K13: =IF($D13="","",MAX(0,$F13-$G13-$H13-$I13-$J13)) | L13: =IF($D13="","",$G13+$H13+$I13+$J13) | M13: =IF($D13="","",IFERROR($L13/$F13,0)) | N13: =IF($D13="","",IFERROR($G13/$L13,0)) | O13: =IF($D13="","",IFERROR(COUNTIF(INDIRECT("'"&$D13&"'!$E$7:$E$500"),"High"),0)) | P13: =IF($D13="","",IFERROR(COUNTIF(INDIRECT("'"&$D13&"'!$E$7:$E$500"),"Medium"),0)) | Q13: =IF($D13="","",IFERROR(COUNTIF(INDIRECT("'"&$D13&"'!$E$7:$E$500"),"Low"),0)) | R13: =IF($D13="","",IFERROR(COUNTIF(INDIRECT("'"&$D13&"'!$D$7:$D$500"),"Functional"),0)) | S13: =IF($D13="","",IFERROR(COUNTIF(INDIRECT("'"&$D13&"'!$D$7:$D$500"),"UI"),0)) | T13: =IF($D13="","",IFERROR(COUNTIF(INDIRECT("'"&$D13&"'!$D$7:$D$500"),"Integration"),0)) | U13: =IF($D13="","",IFERROR(COUNTIF(INDIRECT("'"&$D13&"'!$D$7:$D$500"),"Database Test Case"),0)) | V13: =IF($D13="","",IFERROR(COUNTIF(INDIRECT("'"&$D13&"'!$J$7:$J$500"),"AI"),0)) | W13: =IF($D13="","",IFERROR(COUNTIF(INDIRECT("'"&$D13&"'!$J$7:$J$500"),"QC"),0)) | X13: =IF($D13="","",IFERROR(COUNTIF(INDIRECT("'"&$D13&"'!$L$7:$L$500"),"Yes"),0)) | Y13: =IF($D13="","",IFERROR(COUNTIF(INDIRECT("'"&$D13&"'!$AM$7:$AM$500"),"Yes"),0)) | Z13: =IF($D13="","",IFERROR(COUNTIF(INDIRECT("'"&$D13&"'!$AN$7:$AN$500"),"Pass"),0)) | AA13: =IF($D13="","",IFERROR(COUNTIF(INDIRECT("'"&$D13&"'!$K$7:$K$500"),"Reviewed"),0)) | AB13: =IF($D13="","",IFERROR(SUMPRODUCT((INDIRECT("'"&$D13&"'!$E$7:$E$500")="High")*(INDIRECT("'"&$D13&"'!$AO$7:$AO$500")<>"")),0)) | AC13: =IF($D13="","",IFERROR(SUMPRODUCT((INDIRECT("'"&$D13&"'!$E$7:$E$500")="Medium")*(INDIRECT("'"&$D13&"'!$AO$7:$AO$500")<>"")),0)) | AD13: =IF($D13="","",IFERROR(SUMPRODUCT((INDIRECT("'"&$D13&"'!$E$7:$E$500")="Low")*(INDIRECT("'"&$D13&"'!$AO$7:$AO$500")<>"")),0)) | AE13: =IF($D13="","",IFERROR(COUNTIF(INDIRECT("'"&$D13&"'!$P$7:$P$500"),"<>"),0)) | AF13: =IF($D13="","",IFERROR(COUNTIF(INDIRECT("'"&$D13&"'!$P$7:$P$500"),"Pass"),0)) | AG13: =IF($D13="","",IFERROR(COUNTIF(INDIRECT("'"&$D13&"'!$P$7:$P$500"),"Fail"),0)) | AH13: =IF($D13="","",IFERROR(COUNTIF(INDIRECT("'"&$D13&"'!$P$7:$P$500"),"Block"),0)) | AI13: =IF($D13="","",IFERROR(COUNTIF(INDIRECT("'"&$D13&"'!$P$7:$P$500"),"N/A"),0)) | AJ13: =IF($D13="","",IFERROR(COUNTIF(INDIRECT("'"&$D13&"'!$U$7:$U$500"),"<>"),0)) | AK13: =IF($D13="","",IFERROR(COUNTIF(INDIRECT("'"&$D13&"'!$U$7:$U$500"),"Pass"),0)) | AL13: =IF($D13="","",IFERROR(COUNTIF(INDIRECT("'"&$D13&"'!$U$7:$U$500"),"Fail"),0)) | AM13: =IF($D13="","",IFERROR(COUNTIF(INDIRECT("'"&$D13&"'!$U$7:$U$500"),"Block"),0)) | AN13: =IF($D13="","",IFERROR(COUNTIF(INDIRECT("'"&$D13&"'!$U$7:$U$500"),"N/A"),0)) | AO13: =IF($D13="","",IFERROR(COUNTIF(INDIRECT("'"&$D13&"'!$Z$7:$Z$500"),"<>"),0)) | AP13: =IF($D13="","",IFERROR(COUNTIF(INDIRECT("'"&$D13&"'!$Z$7:$Z$500"),"Pass"),0)) | AQ13: =IF($D13="","",IFERROR(COUNTIF(INDIRECT("'"&$D13&"'!$Z$7:$Z$500"),"Fail"),0)) | AR13: =IF($D13="","",IFERROR(COUNTIF(INDIRECT("'"&$D13&"'!$Z$7:$Z$500"),"Block"),0)) | AS13: =IF($D13="","",IFERROR(COUNTIF(INDIRECT("'"&$D13&"'!$Z$7:$Z$500"),"N/A"),0)) | AT13: =IF($D13="","",IFERROR(COUNTIF(INDIRECT("'"&$D13&"'!$AE$7:$AE$500"),"<>"),0)) | AU13: =IF($D13="","",IFERROR(COUNTIF(INDIRECT("'"&$D13&"'!$AE$7:$AE$500"),"Pass"),0)) | AV13: =IF($D13="","",IFERROR(COUNTIF(INDIRECT("'"&$D13&"'!$AE$7:$AE$500"),"Fail"),0)) | AW13: =IF($D13="","",IFERROR(COUNTIF(INDIRECT("'"&$D13&"'!$AE$7:$AE$500"),"Block"),0)) | AX13: =IF($D13="","",IFERROR(COUNTIF(INDIRECT("'"&$D13&"'!$AE$7:$AE$500"),"N/A"),0)) | AY13: =IF($D13="","",IFERROR(COUNTIF(INDIRECT("'"&$D13&"'!$AJ$7:$AJ$500"),"<>"),0)) | AZ13: =IF($D13="","",IFERROR(COUNTIF(INDIRECT("'"&$D13&"'!$AJ$7:$AJ$500"),"Pass"),0)) | BA13: =IF($D13="","",IFERROR(COUNTIF(INDIRECT("'"&$D13&"'!$AJ$7:$AJ$500"),"Fail"),0)) | BB13: =IF($D13="","",IFERROR(COUNTIF(INDIRECT("'"&$D13&"'!$AJ$7:$AJ$500"),"Block"),0)) | BC13: =IF($D13="","",IFERROR(COUNTIF(INDIRECT("'"&$D13&"'!$AJ$7:$AJ$500"),"N/A"),0))
B14: =IF($D14="","",ROW()-3) | F14: =IF($D14="","",IFERROR(COUNTIF(INDIRECT("'"&$D14&"'!$C$7:$C$500"),"?*"),0)) | G14: =IF($D14="","",IFERROR(COUNTIF(INDIRECT("'"&$D14&"'!$AO$7:$AO$500"),"Pass"),0)) | H14: =IF($D14="","",IFERROR(COUNTIF(INDIRECT("'"&$D14&"'!$AO$7:$AO$500"),"Fail"),0)) | I14: =IF($D14="","",IFERROR(COUNTIF(INDIRECT("'"&$D14&"'!$AO$7:$AO$500"),"Block"),0)) | J14: =IF($D14="","",IFERROR(COUNTIF(INDIRECT("'"&$D14&"'!$AO$7:$AO$500"),"N/A"),0)) | K14: =IF($D14="","",MAX(0,$F14-$G14-$H14-$I14-$J14)) | L14: =IF($D14="","",$G14+$H14+$I14+$J14) | M14: =IF($D14="","",IFERROR($L14/$F14,0)) | N14: =IF($D14="","",IFERROR($G14/$L14,0)) | O14: =IF($D14="","",IFERROR(COUNTIF(INDIRECT("'"&$D14&"'!$E$7:$E$500"),"High"),0)) | P14: =IF($D14="","",IFERROR(COUNTIF(INDIRECT("'"&$D14&"'!$E$7:$E$500"),"Medium"),0)) | Q14: =IF($D14="","",IFERROR(COUNTIF(INDIRECT("'"&$D14&"'!$E$7:$E$500"),"Low"),0)) | R14: =IF($D14="","",IFERROR(COUNTIF(INDIRECT("'"&$D14&"'!$D$7:$D$500"),"Functional"),0)) | S14: =IF($D14="","",IFERROR(COUNTIF(INDIRECT("'"&$D14&"'!$D$7:$D$500"),"UI"),0)) | T14: =IF($D14="","",IFERROR(COUNTIF(INDIRECT("'"&$D14&"'!$D$7:$D$500"),"Integration"),0)) | U14: =IF($D14="","",IFERROR(COUNTIF(INDIRECT("'"&$D14&"'!$D$7:$D$500"),"Database Test Case"),0)) | V14: =IF($D14="","",IFERROR(COUNTIF(INDIRECT("'"&$D14&"'!$J$7:$J$500"),"AI"),0)) | W14: =IF($D14="","",IFERROR(COUNTIF(INDIRECT("'"&$D14&"'!$J$7:$J$500"),"QC"),0)) | X14: =IF($D14="","",IFERROR(COUNTIF(INDIRECT("'"&$D14&"'!$L$7:$L$500"),"Yes"),0)) | Y14: =IF($D14="","",IFERROR(COUNTIF(INDIRECT("'"&$D14&"'!$AM$7:$AM$500"),"Yes"),0)) | Z14: =IF($D14="","",IFERROR(COUNTIF(INDIRECT("'"&$D14&"'!$AN$7:$AN$500"),"Pass"),0)) | AA14: =IF($D14="","",IFERROR(COUNTIF(INDIRECT("'"&$D14&"'!$K$7:$K$500"),"Reviewed"),0)) | AB14: =IF($D14="","",IFERROR(SUMPRODUCT((INDIRECT("'"&$D14&"'!$E$7:$E$500")="High")*(INDIRECT("'"&$D14&"'!$AO$7:$AO$500")<>"")),0)) | AC14: =IF($D14="","",IFERROR(SUMPRODUCT((INDIRECT("'"&$D14&"'!$E$7:$E$500")="Medium")*(INDIRECT("'"&$D14&"'!$AO$7:$AO$500")<>"")),0)) | AD14: =IF($D14="","",IFERROR(SUMPRODUCT((INDIRECT("'"&$D14&"'!$E$7:$E$500")="Low")*(INDIRECT("'"&$D14&"'!$AO$7:$AO$500")<>"")),0)) | AE14: =IF($D14="","",IFERROR(COUNTIF(INDIRECT("'"&$D14&"'!$P$7:$P$500"),"<>"),0)) | AF14: =IF($D14="","",IFERROR(COUNTIF(INDIRECT("'"&$D14&"'!$P$7:$P$500"),"Pass"),0)) | AG14: =IF($D14="","",IFERROR(COUNTIF(INDIRECT("'"&$D14&"'!$P$7:$P$500"),"Fail"),0)) | AH14: =IF($D14="","",IFERROR(COUNTIF(INDIRECT("'"&$D14&"'!$P$7:$P$500"),"Block"),0)) | AI14: =IF($D14="","",IFERROR(COUNTIF(INDIRECT("'"&$D14&"'!$P$7:$P$500"),"N/A"),0)) | AJ14: =IF($D14="","",IFERROR(COUNTIF(INDIRECT("'"&$D14&"'!$U$7:$U$500"),"<>"),0)) | AK14: =IF($D14="","",IFERROR(COUNTIF(INDIRECT("'"&$D14&"'!$U$7:$U$500"),"Pass"),0)) | AL14: =IF($D14="","",IFERROR(COUNTIF(INDIRECT("'"&$D14&"'!$U$7:$U$500"),"Fail"),0)) | AM14: =IF($D14="","",IFERROR(COUNTIF(INDIRECT("'"&$D14&"'!$U$7:$U$500"),"Block"),0)) | AN14: =IF($D14="","",IFERROR(COUNTIF(INDIRECT("'"&$D14&"'!$U$7:$U$500"),"N/A"),0)) | AO14: =IF($D14="","",IFERROR(COUNTIF(INDIRECT("'"&$D14&"'!$Z$7:$Z$500"),"<>"),0)) | AP14: =IF($D14="","",IFERROR(COUNTIF(INDIRECT("'"&$D14&"'!$Z$7:$Z$500"),"Pass"),0)) | AQ14: =IF($D14="","",IFERROR(COUNTIF(INDIRECT("'"&$D14&"'!$Z$7:$Z$500"),"Fail"),0)) | AR14: =IF($D14="","",IFERROR(COUNTIF(INDIRECT("'"&$D14&"'!$Z$7:$Z$500"),"Block"),0)) | AS14: =IF($D14="","",IFERROR(COUNTIF(INDIRECT("'"&$D14&"'!$Z$7:$Z$500"),"N/A"),0)) | AT14: =IF($D14="","",IFERROR(COUNTIF(INDIRECT("'"&$D14&"'!$AE$7:$AE$500"),"<>"),0)) | AU14: =IF($D14="","",IFERROR(COUNTIF(INDIRECT("'"&$D14&"'!$AE$7:$AE$500"),"Pass"),0)) | AV14: =IF($D14="","",IFERROR(COUNTIF(INDIRECT("'"&$D14&"'!$AE$7:$AE$500"),"Fail"),0)) | AW14: =IF($D14="","",IFERROR(COUNTIF(INDIRECT("'"&$D14&"'!$AE$7:$AE$500"),"Block"),0)) | AX14: =IF($D14="","",IFERROR(COUNTIF(INDIRECT("'"&$D14&"'!$AE$7:$AE$500"),"N/A"),0)) | AY14: =IF($D14="","",IFERROR(COUNTIF(INDIRECT("'"&$D14&"'!$AJ$7:$AJ$500"),"<>"),0)) | AZ14: =IF($D14="","",IFERROR(COUNTIF(INDIRECT("'"&$D14&"'!$AJ$7:$AJ$500"),"Pass"),0)) | BA14: =IF($D14="","",IFERROR(COUNTIF(INDIRECT("'"&$D14&"'!$AJ$7:$AJ$500"),"Fail"),0)) | BB14: =IF($D14="","",IFERROR(COUNTIF(INDIRECT("'"&$D14&"'!$AJ$7:$AJ$500"),"Block"),0)) | BC14: =IF($D14="","",IFERROR(COUNTIF(INDIRECT("'"&$D14&"'!$AJ$7:$AJ$500"),"N/A"),0))
